Traceback (most recent call last):
  File "/mnt/c/Users/davi_/Documents/Render/mi_api_backend/manage.py", line 10, in main
    from django.core.management import execute_from_command_line
ModuleNotFoundError: No module named 'django'

The above exception was the direct cause of the following exception:

Traceback (most recent call last):
  File "/mnt/c/Users/davi_/Documents/Render/mi_api_backend/manage.py", line 21, in <module>
    main()
  File "/mnt/c/Users/davi_/Documents/Render/mi_api_backend/manage.py", line 12, in main
    raise ImportError(
ImportError: Couldn't import Django. Are you sure it's installed and available on your PYTHONPATH environment variable? Did you forget to activate a virtual environment?
